Workbook

Sheet Изчисление
A1: За лек автомобил 1 | L1: За лек автомобил 2
A3: μ ср 1 | B3: 0.7 | E3: среден коефициент на сцепление за съответния пътен участък | L3: μ ср 2 | M3: 0.7
A4: σ 1 | B4: 8.1 | C4: метра | E4: път изминат от масовия център на автомобила след удара | L4: σ 2 | M4: 18 | N4: метра
A5: α° | B5: 0 | C5: градуса | E5: ъгъл на наклон на пътното платно | L5: α° | M5: 0 | N5: градуса
A6: j 1 | B6: =(B3*COS(RADIANS(B5))-SIN(RADIANS(B5)))*9.81 -> 6.87 | C6: м/сек² | E6: спирачно закъснение | L6: j 2 | M6: =(M3*COS(RADIANS(M5))-SIN(RADIANS(M5)))*9.81 -> 6.87 | N6: м/сек²
A7: Vy 1 | B7: =B8/3.6 -> 0 | C7: м/сек | E7: скорост погасена при удара (ако има такъв в края на движението на автомобила) | L7: Vy 2 | M7: =M8/3.6 -> 0 | N7: м/сек
B8: 0 | C8: км/ч | M8: 0 | N8: км/ч
A10: u 1 | B10: =SQRT(2*(B6*B4)+B7^2) -> 10.5 | C10: м/сек | F10: Скорост на масовия център след удара | L10: u 2 | M10: =SQRT(2*(M6*M4)+M7^2) -> 15.7 | N10: м/сек
B11: =B10*3.6 -> 37.8 | C11: км/ч | M11: =M10*3.6 -> 56.5 | N11: км/ч
A13: α 1 = | B13: 0 | D13: - ъгъл измерен от абсцисната ос до скоростта на масовия център преди удара | L13: α 2 = | M13: 188
A14: β 1 = | B14: 341 | D14: - ъгъл измерен от абсцисната ос до скоростта на масовия център след удара | L14: β 2 = | M14: 186
A15: m 1 = | B15: 1250 | C15: кг. | D15: - пълна маса на автомобила | L15: m 2 = | M15: 1420 | N15: кг.
A16: u 1 = | B16: =B10 -> 10.5 | C16: м/с | D16: - скорост на масовия център след удара | L16: u 2 = | M16: =M10 -> 15.7 | N16: м/сек
A18: α s | B18: 9 | D18: - ъгъл на директрисата на ударния импулс
A19: к | B19: 140 | D19: - коефициент на възстановяване
A20: k | B20: =(B19-100)% -> 0.4 | H20: Определяне скоростта на превозните средства в момента на удара
A22: V1у Моментум | B22: =((SIN(RADIANS(B14-M13))*B15*B16) + (SIN(RADIANS(M14-M13))*M15*M16))/(SIN(RADIANS(B13-M13))*B15) -> 29.8 | C22: м/с | D22: - скорост на превозните средства в момента на удара | L22: V у2 Моментум | M22: =(SIN(RADIANS(B14-B13))*B15*B16 + SIN(RADIANS(M14-B13))*M15*M16)/(SIN(RADIANS(M13-B13))*M15) -> 33.4 | N22: м/с
B23: =B22*3.6 -> 107.3 | C23: км/ч | F23: Моментум 360 | M23: =M22*3.6 -> 120.2 | N23: км/ч
A25: V1у Теория | B25: =R30 -> 29.5 | C25: м/сек | F25: Теория на удара | L25: Vу2 Теория | M25: =Z30 -> 33.2 | N25: м/сек
B26: =R31 -> 106.2 | C26: км/ч | M26: =Z31 -> 119.5 | N26: км/ч | U26: a11 | V26: =COS(RADIANS(B13))*B15 -> 1250 | W26: кг.
A27: План на скоростите "Моментум 360" | I27: План на скоростите теория на удара | U27: a12 | V27: =COS(RADIANS(M13))*M15 -> -1406.18 | W27: кг.
U28: a21 | V28: =-COS(RADIANS(B13-B18)) -> -0.99
U29: a22 | V29: =COS(RADIANS(M13-B18)) -> -1
Q30: Vу1 | R30: =((V29*V30)-(V27*V31))/((V26*V29)-(V28*V27)) -> 29.5 | S30: м/сек | U30: b1 | V30: =(COS(RADIANS(B14))*B15*B10)+(COS(RADIANS(M14))*M15*M10) -> -9761.94 | W30: N/сек | Y30: Vу2 | Z30: =((V26*V31)-(V28*V30))/((V26*V29)-(V28*V27)) -> 33.2 | AA30: м/сек
R31: =R30*3.6 -> 106.2 | S31: км/ч | U31: b2 | V31: =(((COS(RADIANS(M14-B18)))*M10)-((COS(RADIANS(B14-B18)))*B10))/B20 -> -62.37 | W31: м/сек | Z31: =Z30*3.6 -> 119.5 | AA31: км/ч
F53: При наличие на спирачни следи преди удара | U53: При наличие на спирачни следи преди удара
A55: tн 1 = | B55: 0 | C55: сек. | D55: - време за нарастване на спирачното закъснение от 0 до маскимум | L55: tн 2 = | M55: 0 | N55: сек. | Q55: tн 1 = | R55: =B55 -> 0 | S55: сек. | T55: - време за нарастване на спирачното закъснение от 0 до маскимум | Z55: tн 2 = | AA55: =M55 -> 0 | AB55: сек.
A56: µ 1 = | B56: =B3 -> 0.7 | L56: µ 2= | M56: =M3 -> 0.7 | Q56: µ 1 = | R56: =B56 -> 0.7 | Z56: µ 2= | AA56: =M56 -> 0.7
A57: α = | B57: =B5 -> 0 | C57: градуси | L57: α = | M57: =M5 -> 0 | N57: градуси | Q57: α = | R57: =B57 -> 0 | S57: градуси | Z57: α = | AA57: =M57 -> 0 | AB57: градуси
A58: j 1 = | B58: =(B56*COS(RADIANS(B57))-SIN(RADIANS(B57)))*9.81 -> 6.87 | C58: м/сек 2 | D58: Максимално спирачно закъснение при оставяне на спирачните следи преди удара | L58: j 2 = | M58: =(M56*COS(RADIANS(M57))-SIN(RADIANS(M57)))*9.81 -> 6.87 | N58: м/сек 2 | Q58: j 1 = | R58: =B58 -> 6.87 | S58: м/сек 2 | T58: Максимално спирачно закъснение при оставяне на спирачните следи преди удара | Z58: j 2 = | AA58: =M58 -> 6.87 | AB58: м/сек 2
A59: S 1 = | B59: 0 | C59: метра | D59: Дължина на спирачните следи преди мястото на удара | L59: S 2 = | M59: 0 | N59: метра | Q59: S 1 = | R59: =B59 -> 0 | S59: метра | T59: Дължина на спирачните следи преди мястото на удара | Z59: S 2 = | AA59: =M59 -> 0 | AB59: метра
A60: b 1 = | B60: 0 | C60: метра | D60: Надлъжна база на автомобила | L60: b 2 = | M60: 0 | N60: метра | Q60: b 1 = | R60: =B60 -> 0 | S60: метра | T60: Надлъжна база на автомобила | Z60: b 2 = | AA60: =M60 -> 0 | AB60: метра
A61: σ 1 = | B61: =B59-B60 -> 0 | C61: метра | D61: Ефективен спирачен път на автомобила | L61: σ 2 = | M61: =M59-M60 -> 0 | N61: метра | Q61: σ 1 = | R61: =B61 -> 0 | S61: метра | T61: Ефективен спирачен път на автомобила | Z61: σ 2 = | AA61: =M61 -> 0 | AB61: метра
A62: Vy 1 = | B62: =B22 -> 29.8 | C62: м/с | D62: Скорост в момента на удара | L62: Vy 1 = | M62: =M22 -> 33.4 | N62: м/с | Q62: Vy 1 = | R62: =R30 -> 29.5 | S62: м/с | T62: Скорост в момента на удара | Z62: Vy 1 = | AA62: =Z30 -> 33.2 | AB62: м/с
Q64: V1 преди удара | R64: =(0.5*R55*R58)+SQRT((2*R58*R61)+R62^2) -> 29.5 | S64: м/с | T64: - скорост на лекия автомобил преди удара | Z64: V2 преди удара | AA64: =(0.5*AA55*AA58)+SQRT((2*AA58*AA61)+AA62^2) -> 33.2 | AB64: м/с
F65: Моментум 360 | R65: =R64*3.6 -> 106.2 | S65: км/ч | AA65: =AA64*3.6 -> 119.5 | AB65: км/ч
A66: V1 преди удара | B66: =(0.5*B55*B58)+SQRT((2*B58*B61)+B62^2) -> 29.8 | C66: м/с | D66: - скорост на лекия автомобил преди удара | L66: V2 преди удара | M66: =(0.5*M55*M58)+SQRT((2*M58*M61)+M62^2) -> 33.4 | N66: м/с
B67: =B66*3.6 -> 107.3 | C67: км/ч | M67: =M66*3.6 -> 120.2 | N67: км/ч
F69: Теория на удара
A70: V1 преди удара | B70: =R64 -> 29.5 | C70: м/с | D70: - скорост на лекия автомобил преди удара | L70: V2 преди удара | M70: =AA64 -> 33.2 | N70: м/с
...

Sheet Текст Моментум 360
A1: Определяне на скоростите на превозните средства след удара
A3: =Изчисление!A1 -> За лек автомобил 1
I5: [5]
A7: u1 - скорост на масовия център на превозното средство след удара
A8: σi1 - път изминат от масовия център на превозното средство след удара
A9: ji1 - максимално спирачно закъснение
A12: αHi - ъгъл на наклона на пътя в дадения участък, знакът „плюс” се поставя при изкачване на превозното средство, а „минус” – при спускане
A13: g = 9,81 м/сек ² - земно ускорение
A14: µ Hi - Среден коефициент на сцепление за съответния пътен участък
A16: μ ср1 = | B16: =Изчисление!B3 -> 0.7 | C16: μ ср1 = kr . µ1
A17: α° = | B17: =Изчисление!B5 -> 0 | C17: градуса
A18: σ 1 = | B18: =Изчисление!B4 -> 8.1 | C18: метра
A19: j 1 = | B19: =Изчисление!B6 -> 6.87 | C19: м/сек²
A20: Vy1 = | B20: =Изчисление!B7 -> 0 | C20: м/сек
B21: =Изчисление!B8 -> 0 | C21: км/ч
A24: След заместване в [5], се получва
A26: u1 = | B26: =Изчисление!B10 -> 10.5 | C26: м/сек
B27: =Изчисление!B11 -> 37.8 | C27: км/ч
A31: =Изчисление!L1 -> За лек автомобил 2
I34: [6]
A36: u2 - скорост на масовия център на превозното средство след удара
A37: µ2 - Среден коефициент на сцепление за съответния пътен участък
A38: σ2 - път изминат от масовия център на превозното средство след удара
A41: αHi - ъгъл на наклона на пътя в дадения участък, знакът „плюс” се поставя при изкачване на превозното средство, а „минус” – при спускане
A42: j2 - максимално спирачно закъснение
A43: g = 9,81 м/сек 2 - земно ускорение
A45: μ ср21 = | B45: =Изчисление!$M$3 -> 0.7 | C45: μ ср2 = kr . µ2
A46: α° = | B46: =Изчисление!M5 -> 0 | C46: градуса
A47: σ 21 = | B47: =Изчисление!M4 -> 18 | C47: метра
A48: j 21 = | B48: =Изчисление!M6 -> 6.87 | C48: м/сек ²
A49: Vy 21 = | B49: =Изчисление!M7 -> 0 | C49: м/сек
B50: =Изчисление!M8 -> 0 | C50: км/ч
A54: След заместване в [6], се получава
A56: u2 = | B56: =Изчисление!M10 -> 15.7 | C56: м/сек
B57: =Изчисление!M11 -> 56.5 | C57: км/ч
A59: Определяне скоростта на превозните средства в момента на удара
A61: =Изчисление!A1 -> За лек автомобил 1
I63: [7]
A66: α1 - ъгъл измерен от абсцисната ос до скоростта на масовия център преди удара
A67: β1 - ъгъл измерен от абсцисната ос до скоростта на масовия център след удара
...

Sheet Текст Теория на удара
A1: Определяне на скоростите на превозните средства след удара
A3: =Изчисление!A1 -> За лек автомобил 1
I5: [5]
A7: u1 - скорост на масовия център на превозното средство след удара
A8: σi1 - път изминат от масовия център на превозното средство след удара
A9: ji1 - максимално спирачно закъснение
A12: αHi - ъгъл на наклона на пътя в дадения участък, знакът „плюс” се поставя при изкачване на превозното средство, а „минус” – при спускане
A13: g = 9,81 м/сек ² - земно ускорение
A14: µ Hi - Среден коефициент на сцепление за съответния пътен участък
A16: μ ср1 = | B16: =Изчисление!B3 -> 0.7 | C16: μ ср1 = kr . µ1
A17: α° = | B17: =Изчисление!B5 -> 0 | C17: градуса
A18: σ 1 = | B18: =Изчисление!B4 -> 8.1 | C18: метра
A19: j 1 = | B19: =Изчисление!B6 -> 6.87 | C19: м/сек²
A20: Vy1 = | B20: =Изчисление!B7 -> 0 | C20: м/сек
B21: =Изчисление!B8 -> 0 | C21: км/ч
A24: След заместване в [5], се получва
A26: u1 = | B26: =Изчисление!B10 -> 10.5 | C26: м/сек
B27: =Изчисление!B11 -> 37.8 | C27: км/ч
A30: =Изчисление!L1 -> За лек автомобил 2
I33: [6]
A35: u2 - скорост на масовия център на превозното средство след удара
A36: µ2 - Среден коефициент на сцепление за съответния пътен участък
A37: σ2 - път изминат от масовия център на превозното средство след удара
A40: αHi - ъгъл на наклона на пътя в дадения участък, знакът „плюс” се поставя при изкачване на превозното средство, а „минус” – при спускане
A41: j2 - максимално спирачно закъснение
A42: g = 9,81 м/сек 2 - земно ускорение
A44: μ ср21 = | B44: =Изчисление!M3 -> 0.7 | C44: μ ср2 = kr . µ2
A45: α° = | B45: =Изчисление!M5 -> 0 | C45: градуса
A46: σ 21 = | B46: =Изчисление!M4 -> 18 | C46: метра
A47: j 21 = | B47: =Изчисление!M6 -> 6.87 | C47: м/сек ²
A48: Vy 21 = | B48: =Изчисление!M7 -> 0 | C48: м/сек
B49: =Изчисление!M8 -> 0 | C49: км/ч
A52: След заместване в [6], се получава
A54: u2 = | B54: =Изчисление!M10 -> 15.7 | C54: м/сек
B55: =Изчисление!M11 -> 56.5 | C55: км/ч
A58: Определяне скоростта на превозните средства в момента на удара
I61: [7]
I65: [8]
A68: Стойност на коефициентите в алгебричната система от уравнения
I70: [9]
...
